Workbook

Sheet Flujo Anual
D1: FLUJO DE CAJA PROYECTADO TECNOLOGÍA FORMAL
A2: E.4.3.1.2
A3: NOMBRE:
A4: FECHA ELABORACION (dd/mm/aaaa): | B4: 13/10/2026 | D4: Expresado en bolivianos
A6: AÑO | B6: 2026 | C6: 2027 | D6: 2028 | E6: 2029 | F6: 2030 | G6: 2031 | H6: 2032 | I6: 2033 | J6: 2034 | K6: 2035 | L6: TOTALES | N6: TASA DE CRECIMIENTO ANUAL
B7: 1° AÑO | C7: 2° AÑO | D7: 3° AÑO | E7: 4° AÑO | F7: 5° AÑO | G7: 6° AÑO | H7: 7° AÑO | I7: 8° AÑO | J7: 9° AÑO | K7: 10° AÑO | L7: 10 AÑOS
A8: Crecimiento esperado (%) ingresos de explotación | B8: =$N$8 -> 0.12 | C8: =$N$8 -> 0.12 | D8: =$N$8 -> 0.12 | E8: =$N$8 -> 0.12 | F8: =$N$8 -> 0.12 | G8: =$N$8 -> 0.12 | H8: =$N$8 -> 0.12 | I8: =$N$8 -> 0.12 | ... K8: =$N$8 -> 0.12 | N8: 0.12
A9: INGRESOS
A10: OPERATIVOS O DE EXPLOTACION
A11: Ingresos de explotación | B11: =Supuestos!$B$4*(1+B8) -> 35512783 | C11: =B11*(1+C8) -> 39774317 | D11: =C11*(1+D8) -> 44547235 | E11: =D11*(1+E8) -> 49892903 | F11: =E11*(1+F8) -> 55880052 | G11: =F11*(1+G8) -> 62585658 | H11: =G11*(1+H8) -> 70095937 | I11: =H11*(1+I8) -> 78507449 | J11: =I11*(1+J8) -> 87928343 | K11: =J11*(1+K8) -> 98479744 | L11: =SUM(B11:K11) -> 6.2320442e+08
A12: Ingresos generados por actividad proyectada | B12: =0 -> 0 | C12: =0 -> 0 | D12: =0 -> 0 | E12: =0 -> 0 | F12: =0 -> 0 | G12: =0 -> 0 | H12: =0 -> 0 | I12: =0 -> 0 | ... K12: =0 -> 0 | L12: =SUM(B12:K12) -> 0
A13: OTROS INGRESOS FUERA DE EXPLOTACION
A14: Otros ingresos fuera de explotación | B14: =0 -> 0 | C14: =0 -> 0 | D14: =0 -> 0 | E14: =0 -> 0 | F14: =0 -> 0 | G14: =0 -> 0 | H14: =0 -> 0 | I14: =0 -> 0 | ... K14: =0 -> 0 | L14: =SUM(B14:K14) -> 0
A15: TOTAL INGRESOS | B15: =B11+B12+B14 -> 35512783 | C15: =C11+C12+C14 -> 39774317 | D15: =D11+D12+D14 -> 44547235 | E15: =E11+E12+E14 -> 49892903 | F15: =F11+F12+F14 -> 55880052 | G15: =G11+G12+G14 -> 62585658 | H15: =H11+H12+H14 -> 70095937 | I15: =I11+I12+I14 -> 78507449 | ... K15: =K11+K12+K14 -> 98479744 | L15: =SUM(B15:K15) -> 6.2320442e+08
A16: GASTOS
A17: COSTO DE VENTA O PRODUCCION
A18: Costos de explotación | B18: =-B15*Supuestos!$B$6 -> -12453511 | C18: =-C15*Supuestos!$B$6 -> -13947932 | D18: =-D15*Supuestos!$B$6 -> -15621684 | E18: =-E15*Supuestos!$B$6 -> -17496286 | F18: =-F15*Supuestos!$B$6 -> -19595840 | G18: =-G15*Supuestos!$B$6 -> -21947341 | H18: =-H15*Supuestos!$B$6 -> -24581022 | I18: =-I15*Supuestos!$B$6 -> -27530745 | ... K18: =-K15*Supuestos!$B$6 -> -34534566 | L18: =SUM(B18:K18) -> -2.1854336e+08
A19: Otros costos de explotación | B19: =0 -> 0 | C19: =0 -> 0 | D19: =0 -> 0 | E19: =0 -> 0 | F19: =0 -> 0 | G19: =0 -> 0 | H19: =0 -> 0 | I19: =0 -> 0 | ... K19: =0 -> 0 | L19: =SUM(B19:K19) -> 0
A20: ADMINISTRATIVO
A21: Gastos de administración | B21: =-B15*Supuestos!$B$7 -> -19340562 | C21: =-C15*Supuestos!$B$7 -> -21661430 | D21: =-D15*Supuestos!$B$7 -> -24260801 | E21: =-E15*Supuestos!$B$7 -> -27172097 | F21: =-F15*Supuestos!$B$7 -> -30432749 | G21: =-G15*Supuestos!$B$7 -> -34084679 | H21: =-H15*Supuestos!$B$7 -> -38174840 | I21: =-I15*Supuestos!$B$7 -> -42755821 | ... K21: =-K15*Supuestos!$B$7 -> -53632902 | L21: =SUM(B21:K21) -> -3.394024e+08
A22: Gastos de comercialización (IT) | B22: =-B15*Supuestos!$B$8 -> -1225191 | C22: =-C15*Supuestos!$B$8 -> -1372213.9 | D22: =-D15*Supuestos!$B$8 -> -1536879.6 | E22: =-E15*Supuestos!$B$8 -> -1721305.2 | F22: =-F15*Supuestos!$B$8 -> -1927861.8 | G22: =-G15*Supuestos!$B$8 -> -2159205.2 | H22: =-H15*Supuestos!$B$8 -> -2418309.8 | I22: =-I15*Supuestos!$B$8 -> -2708507 | ... K22: =-K15*Supuestos!$B$8 -> -3397551.2 | L22: =SUM(B22:K22) -> -21500553
A23: Gastos generales | B23: =0 -> 0 | C23: =0 -> 0 | D23: =0 -> 0 | E23: =0 -> 0 | F23: =0 -> 0 | G23: =0 -> 0 | H23: =0 -> 0 | I23: =0 -> 0 | ... K23: =0 -> 0 | L23: =SUM(B23:K23) -> 0
A24: Otros gastos | B24: =0 -> 0 | C24: =0 -> 0 | D24: =0 -> 0 | E24: =0 -> 0 | F24: =0 -> 0 | G24: =0 -> 0 | H24: =0 -> 0 | I24: =0 -> 0 | ... K24: =0 -> 0 | L24: =SUM(B24:K24) -> 0
A25: Depreciaciones | B25: =-Supuestos!$B$10 -> -496357 | C25: =-Supuestos!$B$10 -> -496357 | D25: =-Supuestos!$B$10 -> -496357 | E25: =-Supuestos!$B$10 -> -496357 | F25: =-Supuestos!$B$10 -> -496357 | G25: =-Supuestos!$B$10 -> -496357 | H25: =-Supuestos!$B$10 -> -496357 | I25: =-Supuestos!$B$10 -> -496357 | ... K25: =-Supuestos!$B$10 -> -496357 | L25: =SUM(B25:K25) -> -4963570
A26: Amortización cargos diferidos | B26: =0 -> 0 | C26: =0 -> 0 | D26: =0 -> 0 | E26: =0 -> 0 | F26: =0 -> 0 | G26: =0 -> 0 | H26: =0 -> 0 | I26: =0 -> 0 | ... K26: =0 -> 0 | L26: =SUM(B26:K26) -> 0
A27: Egresos/Ingresos que no generan flujo de efectivo (corrección monetaria) | B27: =-B15*Supuestos!$B$9 -> -2083327.7 | C27: =-C15*Supuestos!$B$9 -> -2333327 | D27: =-D15*Supuestos!$B$9 -> -2613326.2 | E27: =-E15*Supuestos!$B$9 -> -2926925.4 | F27: =-F15*Supuestos!$B$9 -> -3278156.4 | G27: =-G15*Supuestos!$B$9 -> -3671535.2 | H27: =-H15*Supuestos!$B$9 -> -4112119.4 | I27: =-I15*Supuestos!$B$9 -> -4605573.8 | ... K27: =-K15*Supuestos!$B$9 -> -5777231.7 | L27: =SUM(B27:K27) -> -36559766
A28: Impuesto al Valor Agregado IVA | B28: =0 -> 0 | C28: =0 -> 0 | D28: =0 -> 0 | E28: =0 -> 0 | F28: =0 -> 0 | G28: =0 -> 0 | H28: =0 -> 0 | I28: =0 -> 0 | ... K28: =0 -> 0 | L28: =SUM(B28:K28) -> 0
A29: Impuesto a las Transacciones IT | B29: =0 -> 0 | C29: =0 -> 0 | D29: =0 -> 0 | E29: =0 -> 0 | F29: =0 -> 0 | G29: =0 -> 0 | H29: =0 -> 0 | I29: =0 -> 0 | ... K29: =0 -> 0 | L29: =SUM(B29:K29) -> 0
A30: FINANCIEROS
A31: Costo financiero BNB | B31: =0 -> 0 | C31: =0 -> 0 | D31: =0 -> 0 | E31: =0 -> 0 | F31: =0 -> 0 | G31: =0 -> 0 | H31: =0 -> 0 | I31: =0 -> 0 | ... K31: =0 -> 0 | L31: =SUM(B31:K31) -> 0
A32: Costo financiero (otras entidades) | B32: =-B50*Supuestos!$B$14 -> -124081.7 | C32: =-C50*Supuestos!$B$14 -> 0 | D32: =-D50*Supuestos!$B$14 -> 0 | E32: =-E50*Supuestos!$B$14 -> 0 | F32: =-F50*Supuestos!$B$14 -> 0 | G32: =-G50*Supuestos!$B$14 -> 0 | H32: =-H50*Supuestos!$B$14 -> 0 | I32: =-I50*Supuestos!$B$14 -> 0 | ... K32: =-K50*Supuestos!$B$14 -> 0 | L32: =SUM(B32:K32) -> -124081.7
A33: IMPUESTOS IUE | B33: =-MAX(0,B15+SUM(B18:B32))*Supuestos!$B$16 -> 0 | C33: =-MAX(0,C15+SUM(C18:C32))*Supuestos!$B$16 -> 0 | D33: =-MAX(0,D15+SUM(D18:D32))*Supuestos!$B$16 -> -4546.8185 | E33: =-MAX(0,E15+SUM(E18:E32))*Supuestos!$B$16 -> -19983.147 | F33: =-MAX(0,F15+SUM(F18:F32))*Supuestos!$B$16 -> -37271.834 | G33: =-MAX(0,G15+SUM(G18:G32))*Supuestos!$B$16 -> -56635.165 | H33: =-MAX(0,H15+SUM(H18:H32))*Supuestos!$B$16 -> -78322.094 | I33: =-MAX(0,I15+SUM(I18:I32))*Supuestos!$B$16 -> -102611.46 | ... K33: =-MAX(0,K15+SUM(K18:K32))*Supuestos!$B$16 -> -160284.12 | L33: =SUM(B33:K33) -> -589470.17
A34: UTILIDAD NETA | B34: =B15+SUM(B18:B33) -> -210247.15 | C34: =C15+SUM(C18:C33) -> -36942.469 | D34: =D15+SUM(D18:D33) -> 13640.456 | E34: =E15+SUM(E18:E33) -> 59949.44 | F34: =F15+SUM(F18:F33) -> 111815.5 | G34: =G15+SUM(G18:G33) -> 169905.49 | H34: =H15+SUM(H18:H33) -> 234966.28 | I34: =I15+SUM(I18:I33) -> 307834.37 | ... K34: =K15+SUM(K18:K33) -> 480852.35 | L34: =SUM(B34:K34) -> 1521220.9
A35: Saldo de caja inicial | B35: =Supuestos!$B$17 -> 18172128 | C35: =B48 -> 19207835 | D35: =C48 -> 21701397 | E35: =D48 -> 24525542 | F35: =E48 -> 27709594 | G35: =F48 -> 31296744 | H35: =G48 -> 35335362 | I35: =H48 -> 39879626 | J35: =I48 -> 44990212 | K35: =J48 -> 50735078 | L35: =B35 -> 18172128
A36: ACTIVIDADES QUE SUMAN AL FLUJO
A37: Depreciación de activos | B37: =-B25 -> 496357 | C37: =-C25 -> 496357 | D37: =-D25 -> 496357 | E37: =-E25 -> 496357 | F37: =-F25 -> 496357 | G37: =-G25 -> 496357 | H37: =-H25 -> 496357 | I37: =-I25 -> 496357 | ... K37: =-K25 -> 496357 | L37: =SUM(B37:K37) -> 4963570
A38: Amortización cargos diferidos | B38: =-B26 -> 0 | C38: =-C26 -> 0 | D38: =-D26 -> 0 | E38: =-E26 -> 0 | F38: =-F26 -> 0 | G38: =-G26 -> 0 | H38: =-H26 -> 0 | I38: =-I26 -> 0 | ... K38: =-K26 -> 0 | L38: =SUM(B38:K38) -> 0
A39: Egresos/ingresos que no generan flujo de efectivo | B39: =-B27 -> 2083327.7 | C39: =-C27 -> 2333327 | D39: =-D27 -> 2613326.2 | E39: =-E27 -> 2926925.4 | F39: =-F27 -> 3278156.4 | G39: =-G27 -> 3671535.2 | H39: =-H27 -> 4112119.4 | I39: =-I27 -> 4605573.8 | ... K39: =-K27 -> 5777231.7 | L39: =SUM(B39:K39) -> 36559766
A40: Financiamiento BNB | B40: 0 | C40: =0 -> 0 | D40: =0 -> 0 | E40: =0 -> 0 | F40: =0 -> 0 | G40: =0 -> 0 | H40: =0 -> 0 | I40: =0 -> 0 | J40: =0 -> 0 | K40: =0 -> 0 | L40: =SUM(B40:K40) -> 0
A41: Financiamiento otros bancos | B41: =0 -> 0 | C41: =0 -> 0 | D41: =0 -> 0 | E41: =0 -> 0 | F41: =0 -> 0 | G41: =0 -> 0 | H41: =0 -> 0 | I41: =0 -> 0 | ... K41: =0 -> 0 | L41: =SUM(B41:K41) -> 0
...

Sheet Flujo 12 Meses
D1: FLUJO DE CAJA PROYECTADO TECNOLOGÍA FORMAL
A3: NOMBRE: | B3: CONFITERIA ELIS
A4: FECHA ELABORACION (dd/mm/aaaa): | B4: 13/10/2026 | D4: Expresado en bolivianos
A6: MES DEL AÑO | B6: ene-26 | C6: feb-26 | D6: mar-26 | E6: abr-26 | F6: may-26 | G6: jun-26 | H6: jul-26 | I6: ago-26 | J6: sep-26 | K6: oct-26 | L6: nov-26 | M6: dic-26 | N6: TOTALES | P6: TASA DE CRECIMIENTO MENSUAL
B7: 1° MES | C7: 2° MES | D7: 3° MES | E7: 4° MES | F7: 5° MES | G7: 6° MES | H7: 7° MES | I7: 8° MES | J7: 9° MES | K7: 10° MES | L7: 11° MES | M7: 12° MES | N7: AÑO 1
A8: Crecimiento esperado (%) ingresos de explotación | B8: =$P$8 -> 0.0374 | C8: =$P$8 -> 0.0374 | D8: =$P$8 -> 0.0374 | E8: =$P$8 -> 0.0374 | F8: =$P$8 -> 0.0374 | G8: =$P$8 -> 0.0374 | H8: =$P$8 -> 0.0374 | I8: =$P$8 -> 0.0374 | ... M8: =$P$8 -> 0.0374 | P8: 0.0374
A9: INGRESOS
A10: OPERATIVOS O DE EXPLOTACION
A11: Ingresos de explotación | B11: =Supuestos!$B$5*(1+B8) -> 2741142.9 | C11: =B11*(1+C8) -> 2843661.7 | D11: =C11*(1+D8) -> 2950014.6 | E11: =D11*(1+E8) -> 3060345.2 | F11: =E11*(1+F8) -> 3174802.1 | G11: =F11*(1+G8) -> 3293539.7 | H11: =G11*(1+H8) -> 3416718.1 | I11: =H11*(1+I8) -> 3544503.3 | J11: =I11*(1+J8) -> 3677067.8 | ... M11: =L11*(1+M8) -> 4105257.1 | N11: =SUM(B11:M11) -> 40578898
A12: Ingresos generados por actividad proyectada | B12: =0 -> 0 | C12: =0 -> 0 | D12: =0 -> 0 | E12: =0 -> 0 | F12: =0 -> 0 | G12: =0 -> 0 | H12: =0 -> 0 | I12: =0 -> 0 | ... M12: =0 -> 0 | N12: =SUM(B12:M12) -> 0
A13: OTROS INGRESOS FUERA DE EXPLOTACION
A14: Otros ingresos fuera de explotación | B14: =0 -> 0 | C14: =0 -> 0 | D14: =0 -> 0 | E14: =0 -> 0 | F14: =0 -> 0 | G14: =0 -> 0 | H14: =0 -> 0 | I14: =0 -> 0 | ... M14: =0 -> 0 | N14: =SUM(B14:M14) -> 0
A15: TOTAL INGRESOS | B15: =B11+B12+B14 -> 2741142.9 | C15: =C11+C12+C14 -> 2843661.7 | D15: =D11+D12+D14 -> 2950014.6 | E15: =E11+E12+E14 -> 3060345.2 | F15: =F11+F12+F14 -> 3174802.1 | G15: =G11+G12+G14 -> 3293539.7 | H15: =H11+H12+H14 -> 3416718.1 | I15: =I11+I12+I14 -> 3544503.3 | ... M15: =M11+M12+M14 -> 4105257.1 | N15: =SUM(B15:M15) -> 40578898
A16: GASTOS
A17: COSTO DE VENTA O PRODUCCION
A18: Costos de explotación | B18: =-B15*Supuestos!$B$6 -> -961255.36 | C18: =-C15*Supuestos!$B$6 -> -997206.31 | D18: =-D15*Supuestos!$B$6 -> -1034501.8 | E18: =-E15*Supuestos!$B$6 -> -1073192.2 | F18: =-F15*Supuestos!$B$6 -> -1113329.6 | G18: =-G15*Supuestos!$B$6 -> -1154968.1 | H18: =-H15*Supuestos!$B$6 -> -1198163.9 | I18: =-I15*Supuestos!$B$6 -> -1242975.2 | ... M18: =-M15*Supuestos!$B$6 -> -1439618.6 | N18: =SUM(B18:M18) -> -14230080
A19: Otros costos de explotación | B19: =0 -> 0 | C19: =0 -> 0 | D19: =0 -> 0 | E19: =0 -> 0 | F19: =0 -> 0 | G19: =0 -> 0 | H19: =0 -> 0 | I19: =0 -> 0 | ... M19: =0 -> 0 | N19: =SUM(B19:M19) -> 0
A20: ADMINISTRATIVO
A21: Gastos de administración | B21: =-B15*Supuestos!$B$7 -> -1492849.6 | C21: =-C15*Supuestos!$B$7 -> -1548682.2 | D21: =-D15*Supuestos!$B$7 -> -1606602.9 | E21: =-E15*Supuestos!$B$7 -> -1666689.9 | F21: =-F15*Supuestos!$B$7 -> -1729024.1 | G21: =-G15*Supuestos!$B$7 -> -1793689.6 | H21: =-H15*Supuestos!$B$7 -> -1860773.6 | I21: =-I15*Supuestos!$B$7 -> -1930366.5 | ... M21: =-M15*Supuestos!$B$7 -> -2235757.8 | N21: =SUM(B21:M21) -> -22099611
A22: Gastos de comercialización (IT) | B22: =-B15*Supuestos!$B$8 -> -94569.431 | C22: =-C15*Supuestos!$B$8 -> -98106.328 | D22: =-D15*Supuestos!$B$8 -> -101775.5 | E22: =-E15*Supuestos!$B$8 -> -105581.91 | F22: =-F15*Supuestos!$B$8 -> -109530.67 | G22: =-G15*Supuestos!$B$8 -> -113627.12 | H22: =-H15*Supuestos!$B$8 -> -117876.77 | I22: =-I15*Supuestos!$B$8 -> -122285.36 | ... M22: =-M15*Supuestos!$B$8 -> -141631.37 | N22: =SUM(B22:M22) -> -1399972
A23: Gastos generales | B23: =0 -> 0 | C23: =0 -> 0 | D23: =0 -> 0 | E23: =0 -> 0 | F23: =0 -> 0 | G23: =0 -> 0 | H23: =0 -> 0 | I23: =0 -> 0 | ... M23: =0 -> 0 | N23: =SUM(B23:M23) -> 0
A24: Otros gastos | B24: =0 -> 0 | C24: =0 -> 0 | D24: =0 -> 0 | E24: =0 -> 0 | F24: =0 -> 0 | G24: =0 -> 0 | H24: =0 -> 0 | I24: =0 -> 0 | ... M24: =0 -> 0 | N24: =SUM(B24:M24) -> 0
A25: Depreciaciones | B25: =-Supuestos!$B$11 -> -41363.083 | C25: =-Supuestos!$B$11 -> -41363.083 | D25: =-Supuestos!$B$11 -> -41363.083 | E25: =-Supuestos!$B$11 -> -41363.083 | F25: =-Supuestos!$B$11 -> -41363.083 | G25: =-Supuestos!$B$11 -> -41363.083 | H25: =-Supuestos!$B$11 -> -41363.083 | I25: =-Supuestos!$B$11 -> -41363.083 | ... M25: =-Supuestos!$B$11 -> -41363.083 | N25: =SUM(B25:M25) -> -496357
A26: Amortización cargos diferidos | B26: =0 -> 0 | C26: =0 -> 0 | D26: =0 -> 0 | E26: =0 -> 0 | F26: =0 -> 0 | G26: =0 -> 0 | H26: =0 -> 0 | I26: =0 -> 0 | ... M26: =0 -> 0 | N26: =SUM(B26:M26) -> 0
A27: Egresos/Ingresos que no generan flujo de efectivo (corrección monetaria) | B27: =-B15*Supuestos!$B$9 -> -160806.86 | C27: =-C15*Supuestos!$B$9 -> -166821.03 | D27: =-D15*Supuestos!$B$9 -> -173060.14 | E27: =-E15*Supuestos!$B$9 -> -179532.59 | F27: =-F15*Supuestos!$B$9 -> -186247.11 | G27: =-G15*Supuestos!$B$9 -> -193212.75 | H27: =-H15*Supuestos!$B$9 -> -200438.9 | I27: =-I15*Supuestos!$B$9 -> -207935.32 | ... M27: =-M15*Supuestos!$B$9 -> -240831.47 | N27: =SUM(B27:M27) -> -2380527.1
A28: Impuesto al Valor Agregado IVA | B28: =0 -> 0 | C28: =0 -> 0 | D28: =0 -> 0 | E28: =0 -> 0 | F28: =0 -> 0 | G28: =0 -> 0 | H28: =0 -> 0 | I28: =0 -> 0 | ... M28: =0 -> 0 | N28: =SUM(B28:M28) -> 0
A29: Impuesto a las Transacciones IT | B29: =0 -> 0 | C29: =0 -> 0 | D29: =0 -> 0 | E29: =0 -> 0 | F29: =0 -> 0 | G29: =0 -> 0 | H29: =0 -> 0 | I29: =0 -> 0 | ... M29: =0 -> 0 | N29: =SUM(B29:M29) -> 0
A30: FINANCIEROS
A31: Costo financiero BNB | B31: =0 -> 0 | C31: =0 -> 0 | D31: =0 -> 0 | E31: =0 -> 0 | F31: =0 -> 0 | G31: =0 -> 0 | H31: =0 -> 0 | I31: =0 -> 0 | ... M31: =0 -> 0 | N31: =SUM(B31:M31) -> 0
A32: Costo financiero (otras entidades) | B32: =-B50*Supuestos!$B$14/12 -> -10340.142 | C32: =-C50*Supuestos!$B$14/12 -> -9478.4631 | D32: =-D50*Supuestos!$B$14/12 -> -8616.7846 | E32: =-E50*Supuestos!$B$14/12 -> -7755.1062 | F32: =-F50*Supuestos!$B$14/12 -> -6893.4277 | G32: =-G50*Supuestos!$B$14/12 -> -6031.7492 | H32: =-H50*Supuestos!$B$14/12 -> -5170.0708 | I32: =-I50*Supuestos!$B$14/12 -> -4308.3923 | ... M32: =-M50*Supuestos!$B$14/12 -> -861.67846 | N32: =SUM(B32:M32) -> -67210.92
A33: IMPUESTOS IUE | B33: =-MAX(0,B15+SUM(B18:B32))*Supuestos!$B$16 -> 0 | C33: =-MAX(0,C15+SUM(C18:C32))*Supuestos!$B$16 -> 0 | D33: =-MAX(0,D15+SUM(D18:D32))*Supuestos!$B$16 -> 0 | E33: =-MAX(0,E15+SUM(E18:E32))*Supuestos!$B$16 -> 0 | F33: =-MAX(0,F15+SUM(F18:F32))*Supuestos!$B$16 -> 0 | G33: =-MAX(0,G15+SUM(G18:G32))*Supuestos!$B$16 -> 0 | H33: =-MAX(0,H15+SUM(H18:H32))*Supuestos!$B$16 -> 0 | I33: =-MAX(0,I15+SUM(I18:I32))*Supuestos!$B$16 -> 0 | ... M33: =-MAX(0,M15+SUM(M18:M32))*Supuestos!$B$16 -> -1298.2857 | N33: =SUM(B33:M33) -> -1981.885
A34: UTILIDAD NETA | B34: =B15+SUM(B18:B33) -> -20041.565 | C34: =C15+SUM(C18:C33) -> -17995.74 | D34: =D15+SUM(D18:D33) -> -15905.629 | E34: =E15+SUM(E18:E33) -> -13769.574 | F34: =F15+SUM(F18:F33) -> -11585.857 | G34: =G15+SUM(G18:G33) -> -9352.6962 | H34: =H15+SUM(H18:H33) -> -7068.2419 | I34: =I15+SUM(I18:I33) -> -4730.5757 | ... M34: =M15+SUM(M18:M33) -> 3894.8572 | N34: =SUM(B34:M34) -> -96841.932
A35: Saldo de caja inicial | B35: =Supuestos!$B$17 -> 18172128 | C35: =B48 -> 18243112 | D35: =C48 -> 18322156 | E35: =D48 -> 18409530 | F35: =E48 -> 18505512 | G35: =F48 -> 18610392 | H35: =G48 -> 18724471 | I35: =H48 -> 18848060 | J35: =I48 -> 18981484 | ... M35: =L48 -> 19443495 | N35: =B35 -> 18172128
A36: ACTIVIDADES QUE SUMAN AL FLUJO
A37: Depreciación de activos | B37: =-B25 -> 41363.083 | C37: =-C25 -> 41363.083 | D37: =-D25 -> 41363.083 | E37: =-E25 -> 41363.083 | F37: =-F25 -> 41363.083 | G37: =-G25 -> 41363.083 | H37: =-H25 -> 41363.083 | I37: =-I25 -> 41363.083 | ... M37: =-M25 -> 41363.083 | N37: =SUM(B37:M37) -> 496357
A38: Amortización cargos diferidos | B38: =-B26 -> 0 | C38: =-C26 -> 0 | D38: =-D26 -> 0 | E38: =-E26 -> 0 | F38: =-F26 -> 0 | G38: =-G26 -> 0 | H38: =-H26 -> 0 | I38: =-I26 -> 0 | ... M38: =-M26 -> 0 | N38: =SUM(B38:M38) -> 0
A39: Egresos/ingresos que no generan flujo de efectivo | B39: =-B27 -> 160806.86 | C39: =-C27 -> 166821.03 | D39: =-D27 -> 173060.14 | E39: =-E27 -> 179532.59 | F39: =-F27 -> 186247.11 | G39: =-G27 -> 193212.75 | H39: =-H27 -> 200438.9 | I39: =-I27 -> 207935.32 | ... M39: =-M27 -> 240831.47 | N39: =SUM(B39:M39) -> 2380527.1
A40: Financiamiento BNB | B40: =0 -> 0 | C40: =0 -> 0 | D40: =0 -> 0 | E40: =0 -> 0 | F40: =0 -> 0 | G40: =0 -> 0 | H40: =0 -> 0 | I40: =0 -> 0 | ... M40: =0 -> 0 | N40: =SUM(B40:M40) -> 0
A41: Financiamiento otros bancos | B41: =0 -> 0 | C41: =0 -> 0 | D41: =0 -> 0 | E41: =0 -> 0 | F41: =0 -> 0 | G41: =0 -> 0 | H41: =0 -> 0 | I41: =0 -> 0 | ... M41: =0 -> 0 | N41: =SUM(B41:M41) -> 0
A42: Otros financiamientos | B42: =0 -> 0 | C42: =0 -> 0 | D42: =0 -> 0 | E42: =0 -> 0 | F42: =0 -> 0 | G42: =0 -> 0 | H42: =0 -> 0 | I42: =0 -> 0 | ... M42: =0 -> 0 | N42: =SUM(B42:M42) -> 0
...

Sheet Flujo Historico 2024-2025
C1: FLUJO DE CAJA DIRECTO
A3: NOMBRE: | B3: CONFITERIA ELIS
A4: FECHA ELABORACION (dd/mm/aaaa): | B4: 13/10/2026 | C4: Expresado en bolivianos
A6: CONCEPTO | B6: AÑO 2024 | C6: AÑO 2025
A7: INGRESOS
A8: OPERATIVOS O DE EXPLOTACION
A9: Ingresos de explotación (cobros por ventas) | B9: =Datos!C20-((Datos!C7+Datos!C8)-(Datos!B7+Datos!B8)) -> 23810536 | C9: =Datos!D20-((Datos!D7+Datos!D8)-(Datos!C7+Datos!C8)) -> 31707842
A10: Ingresos generados por actividad proyectada | B10: =0 -> 0 | C10: =0 -> 0
A11: OTROS INGRESOS FUERA DE EXPLOTACION
A12: Otros ingresos fuera de explotación | B12: =Datos!C21 -> 0 | C12: =Datos!D21 -> 0
A13: TOTAL INGRESOS | B13: =B9+B10+B12 -> 23810536 | C13: =C9+C10+C12 -> 31707842
A14: GASTOS
A15: COSTO DE VENTA O PRODUCCION
A16: Costos de explotación (pagos) | B16: =-(Datos!C22+(Datos!C9-Datos!B9)) -> -19591925 | C16: =-(Datos!D22+(Datos!D9-Datos!C9)) -> -10821206
A17: Otros costos de explotación | B17: =0 -> 0 | C17: =0 -> 0
A18: ADMINISTRATIVO
A19: Gastos de administración (pagos) | B19: =-(Datos!C23-(Datos!C11-Datos!B11)-((Datos!C12+Datos!C13+Datos!C14)-(Datos!B12+Datos!B13+Datos!B14))) -> -723264.32 | C19: =-(Datos!D23-(Datos!D11-Datos!C11)-((Datos!D12+Datos!D13+Datos!D14)-(Datos!C12+Datos!C13+Datos!C14))) -> -14251229
A20: Gastos de comercialización | B20: =-Datos!C24 -> -821463.49 | C20: =-Datos!D24 -> -1093920.5
A21: Gastos generales | B21: =0 -> 0 | C21: =0 -> 0
A22: Otros gastos | B22: =0 -> 0 | C22: =0 -> 0
A23: Depreciaciones | B23: =-Datos!C25 -> -496357 | C23: =-Datos!D25 -> -496357
A24: Amortización cargos diferidos | B24: =0 -> 0 | C24: =0 -> 0
A25: Egresos/Ingresos que no generan flujo de efectivo (corrección monetaria) | B25: =-(Datos!C27+Datos!C29) -> -221317 | C25: =-(Datos!D27+Datos!D29) -> -1860114
A26: Impuesto al Valor Agregado IVA | B26: =0 -> 0 | C26: =0 -> 0
A27: Impuesto a las Transacciones IT | B27: =0 -> 0 | C27: =0 -> 0
A28: FINANCIEROS
A29: Costo financiero BNB | B29: =0 -> 0 | C29: =0 -> 0
A30: Costo financiero (otras entidades) | B30: =-Datos!C26 -> -195138 | C30: =-Datos!D26 -> -178588
A31: IMPUESTOS IUE | B31: =-Datos!C28 -> 0 | C31: =-Datos!D28 -> 0
A32: UTILIDAD NETA (base flujo) | B32: =B13+B16+B17+SUM(B19:B27)+B29+B30+B31 -> 1761071.2 | C32: =C13+C16+C17+SUM(C19:C27)+C29+C30+C31 -> 3006427.1
A33: Saldo de caja inicial (caja y bancos + depósitos a plazo) | B33: =Datos!B5+Datos!B6 -> 12179656 | C33: =Datos!C5+Datos!C6 -> 14241966
A34: ACTIVIDADES QUE SUMAN AL FLUJO
A35: Depreciación de activos | B35: =-B23 -> 496357 | C35: =-C23 -> 496357
A36: Amortización cargos diferidos | B36: =-B24 -> 0 | C36: =-C24 -> 0
A37: Egresos/ingresos que no generan flujo de efectivo | B37: =-B25 -> 221317 | C37: =-C25 -> 1860114
A38: Financiamiento BNB | B38: =0 -> 0 | C38: =0 -> 0
A39: Financiamiento otros bancos | B39: =MAX(Datos!C15-Datos!B15,0) -> 0 | C39: =MAX(Datos!D15-Datos!C15,0) -> 0
A40: Otros financiamientos | B40: =0 -> 0 | C40: =0 -> 0
A41: ACTIVIDADES QUE RESTAN AL FLUJO
A42: Amortización capital BNB | B42: =0 -> 0 | C42: =0 -> 0
...

Sheet Supuestos
A1: SUPUESTOS DE LA PROYECCIÓN (base: gestión 2025 auditada)
A4: Ventas 2025 (Bs) | B4: =Datos!D20 -> 31707842
A5: Ventas mensuales promedio 2025 (Bs) | B5: =B4/12 -> 2642320.2
A6: % Costo de explotación sobre ventas | B6: =Datos!D22/Datos!D20 -> 0.35067685
A7: % Gastos de administración sobre ventas | B7: =Datos!D23/Datos!D20 -> 0.54460846
A8: % Gastos de comercialización (IT) sobre ventas | B8: =Datos!D24/Datos!D20 -> 0.0345
A9: % Corrección monetaria sobre ventas (no es efectivo) | B9: =Datos!D27/Datos!D20 -> 0.058664163
A10: Depreciación anual (Bs) | B10: =Datos!D25 -> 496357
A11: Depreciación mensual (Bs) | B11: =B10/12 -> 41363.083
A12: Inversiones (gastos de capital) anuales (Bs) | B12: =(Datos!D10-Datos!C10)+Datos!D25 -> 299179.32
A13: Inversiones mensuales (Bs) | B13: =B12/12 -> 24931.61
A14: Tasa de interés anual de la deuda | B14: =Datos!D26/((Datos!C15+Datos!D15)/2) -> 0.11993773
A15: Deuda con instituciones financieras LP al 31/12/2025 (Bs) | B15: =Datos!D15 -> 1034551
A16: Tasa del IUE | B16: 0.25
A17: Saldo de caja inicial: caja y bancos + depósitos a plazo (Bs) | B17: =Datos!D5+Datos!D6 -> 18172128
A19: Supuestos generales
A20: - Se cobra y se paga al contado: no cambian cuentas por cobrar, existencias, proveedores ni impuestos por pagar.
A21: - La deuda a LP se paga en partes iguales durante el primer año (mensual en el flujo de 12 meses; todo en el año 1 en el flujo anual).
A22: - Intereses = saldo de la deuda x tasa (tasa 2025 = gasto financiero / deuda promedio).
A23: - IUE = 25% de la utilidad antes de impuestos, solo si es positiva. Inversiones y depreciación se mantienen iguales a 2025.
A24: - La proyección empieza en enero 2026, justo después del cierre auditado 2025.

Sheet Datos
A1: CONFITERIA ELIS - Datos fuente (estados financieros auditados, Bs)
A3: Concepto | B3: 2023 | C3: 2024 | D3: 2025
A4: BALANCE GENERAL
A5: Caja y bancos | B5: 6090169.8 | C5: 8142043 | D5: 12072205
A6: Depósitos a plazo fijo y otros | B6: 6089486.6 | C6: 6099923 | D6: 6099923
A7: Documentos por cobrar del giro | B7: 0 | C7: 6982712 | D7: 6982712
A8: Gastos anticipados | B8: 6982712 | C8: 0 | D8: 0
A9: Existencias | B9: 384212 | C9: 365000 | D9: 67000
A10: Activo fijo neto | B10: 2051765.6 | C10: 1630677.7 | D10: 1433500
A11: Provisiones y retenciones | B11: 2088054 | C11: 2481153.4 | D11: 1444587
A12: Impuestos por pagar | B12: 679535.2 | C12: 6901437 | D12: 10955133
A13: Impuestos a las utilidades IUE por pagar | B13: 139996 | C13: 0 | D13: 0
A14: Otro pasivo no corriente (Plan de pagos SIN) | B14: 4813214 | C14: 0 | D14: 0
A15: Instituciones financieras a largo plazo | B15: 3266129.5 | C15: 1943461 | D15: 1034551
A16: Total patrimonio | B16: 10611417 | C16: 11894305 | D16: 13221069
A17: Utilidad (pérdida) del ejercicio - Balance | B17: 398988.18 | C17: 80068 | D17: -308704
A19: ESTADO DE RESULTADOS
A20: Ingresos de explotación | B20: 20943303 | C20: 23810536 | D20: 31707842
A21: Ingresos fuera de explotación | B21: 174486.95 | C21: 0 | D21: 0
A22: Costos de explotación | B22: 12873104 | C22: 19611137 | D22: 11119206
A23: Gastos de administración | B23: 5203367.7 | C23: 2385055.5 | D23: 17268359
A24: Gastos de comercialización (impuestos) | B24: 722183 | C24: 821463.49 | D24: 1093920.5
A25: Depreciaciones | B25: 631161.92 | C25: 496357 | D25: 496357
A26: Gastos financieros | B26: 938770.31 | C26: 195138 | D26: 178588
A27: Corrección monetaria | B27: 189220.04 | C27: 221317 | D27: 1860114
A28: Impuesto a las utilidades IUE | B28: 139996 | C28: 0 | D28: 0
A29: Ajustes de la gestión | B29: 20999.38 | C29: 0 | D29: 0
A30: Utilidad (pérdida) - Estado de Resultados | B30: 398988.08 | C30: 80068 | D30: -308702.55
